Workbook

Sheet VT Standard configs
A2: Parameter | D2: UNIT | E2: VT schedules export | F2: LD export | G2: warning | H2: ID | K2: Notes | M2: 1 | N2: 2 | O2: 3 | P2: 4 | Q2: 5 | R2: 6 | S2: 7 | T2: 8 | U2: 9
A3: Configuration short name | F3: No | H3: - | M3: =CONCATENATE(M11,"_",M19,"_",M29,"_",M20,"kg-",M22,"ms-",M34,"x",M35,"x",M37,"_",M45) -> Traction - MR_CWT-Left_Front_630kg-1.6ms-1100x1400x2200_2L | N3: =CONCATENATE(N11,"_",N19,"_",N29,"_",N20,"kg-",N22,"ms-",N34,"x",N35,"x",N37,"_",N45) -> Traction - MRL_CWT-Left_Front_1000kg-1.6ms-1100x2100x2200_2L | O3: =CONCATENATE(O11,"_",O19,"_",O29,"_",O20,"kg-",O22,"ms-",O34,"x",O35,"x",O37,"_",O45) -> Traction - MRL_CWT-Right_Front_1275kg-1ms-1200x2300x2300_2R | P3: =CONCATENATE(P11,"_",P19,"_",P29,"_",P20,"kg-",P22,"ms-",P34,"x",P35,"x",P37,"_",P45) -> Traction - MRL_CWT-Left_Front + Rear_1350kg-1.6ms-2000x1500x2300_2C | Q3: =CONCATENATE(Q11,"_",Q19,"_",Q29,"_",Q20,"kg-",Q22,"ms-",Q34,"x",Q35,"x",Q37,"_",Q45) -> Traction - MRL_CWT-Left_Front_1600kg-1ms-2100x1600x2400_2C | R3: =CONCATENATE(R11,"_",R19,"_",R29,"_",R20,"kg-",R22,"ms-",R34,"x",R35,"x",R37,"_",R45) -> Traction - MRL_CWT-Left_Front + Rear_1850kg-1ms-Wrong shapexnon std. Cabin typex2400_2C | S3: =CONCATENATE(S11,"_",S19,"_",S29,"_",S20,"kg-",S22,"ms-",S34,"x",S35,"x",S37,"_",S45) -> Traction - MRL_CWT-Left_Front + Rear_2000kg-1.6ms-1500x2700x2300_4C | T3: =CONCATENATE(T11,"_",T19,"_",T29,"_",T20,"kg-",T22,"ms-",T34,"x",T35,"x",T37,"_",T45) -> Traction - MRL_CWT-Right_Front + Rear_2500kg-1ms-1800x2700x2300_4C | U3: =CONCATENATE(U11,"_",U19,"_",U29,"_",U20,"kg-",U22,"ms-",U34,"x",U35,"x",U37,"_",U45) -> Traction - MRL_CWT-Left_Front + Rear_3500kg-1ms-2100x3000x2400_4C
A4: System name | D4: - | E4: yes | F4: Shaft0.L_SystemTab.SYS_ELEV_DESC | G4: yes | H4: - | X4: Variable formula in the row
A5: Building part | D5: - | E5: yes | F5: No | G5: - | H5: -
A6: Buidlign section | D6: - | E6: yes | F6: no | G6: - | H6: -
A7: Grid position | D7: - | E7: yes | F7: no | G7: - | H7: -
A8: Plan code | D8: - | E8: yes | F8: no | G8: - | H8: -
A9: Drawing No.: internal | D9: - | E9: yes | F9: no | G9: - | H9: -
A11: System category | D11: - | E11: yes | F11: no | G11: - | H11: - | M11: Traction - MR | N11: Traction - MRL | O11: Traction - MRL | P11: Traction - MRL | Q11: Traction - MRL | R11: Traction - MRL | S11: Traction - MRL | T11: Traction - MRL | U11: Traction - MRL
A12: Functions | D12: - | E12: yes | F12: no | G12: - | H12: -
A13: Construction use | D13: [y/n] | E13: yes | F13: no | G13: - | H13: - | M13: no | N13: no | O13: no | P13: no | Q13: no | R13: no | S13: no | T13: no | U13: no
A14: Brand | D14: - | E14: yes | F14: no | G14: - | H14: -
A15: Factory number | D15: - | E15: yes | F15: no | G15: - | H15: -
A17: General Specification
A18: Group Control | D18: - | E18: yes | F18: no | G18: - | H18: -
A19: Counterweight location | D19: - | E19: yes | F19: yes, info | G19: yes | H19: - | M19: CWT-Left | N19: CWT-Left | O19: CWT-Right | P19: CWT-Left | Q19: CWT-Left | R19: CWT-Left | S19: CWT-Left | T19: CWT-Right | U19: CWT-Left
A20: Load capacity | D20: [kg] | E20: yes | F20: Shaft0.L_SystemTab.SYS_ENTERED_LOAD | G20: yes | H20: - | M20: 630 | N20: 1000 | O20: 1275 | P20: 1350 | Q20: 1600 | R20: 1850 | S20: 2000 | T20: 2500 | U20: 3500
A21: Permissible number of persons | D21: [Pers.] | E21: yes | F21: Shaft0.L_SystemTab.SYS_ENTERED_PERSON | G21: yes | H21: - | K21: Keep this as a standard value for each type of lift | M21: 8 | N21: 13 | O21: 17 | P21: 18 | Q21: 21 | R21: 25 | S21: 27 | T21: 33 | U21: 47
A22: Speed | D22: [m/s] | E22: yes | F22: Shaft0.L_SystemTab.SYS_TRAVEL_SPEED_UP | G22: yes | H22: - | M22: 1.6 | N22: 1.6 | O22: 1 | P22: 1.6 | Q22: 1 | R22: 1 | S22: 1.6 | T22: 1 | U22: 1
A23: Acceleration | D23: [m/s²] | E23: yes | F23: no | G23: - | H23: -
A24: Jerk | D24: [m/s³] | E24: yes | F24: no | G24: - | H24: -
A25: Travel height | D25: [m] | E25: yes | F25: no | G25: - | H25: - | M25: 20
A26: Stops | D26: [Stck.] | E26: yes | G26: yes | H26: - | K26: MANUAL | M26: 5
A27: Number of floors | D27: [Stck.] | F27: FLL.FLL_COUNT | G27: yes | H27: - | M27: 6
A28: Number of shaft doors | D28: [Stck.] | E28: yes | F28: no | G28: - | H28: -
A29: Access type | E29: yes | F29: yes, info | G29: yes | H29: - | M29: Front | N29: Front | O29: Front | P29: Front + Rear | Q29: Front | R29: Front + Rear | S29: Front + Rear | T29: Front + Rear | U29: Front + Rear
A30: Accessible rooms / cwt safety | D30: [y/n] | E30: yes | F30: no | G30: - | H30: - | M30: no | N30: no | O30: no | P30: no | Q30: no | R30: no | S30: no | T30: no | U30: no
A32: Layout Information
A33: Cabin type/shape | E33: yes | F33: no | G33: - | M33: Deep | N33: Deep | O33: Deep | P33: Wide | Q33: Wide | R33: Deep | S33: Deep | T33: Deep | U33: Deep
A34: Cabin width (clear) | D34: [mm] | E34: yes | F34: Shaft0.Car.CW | G34: yes | H34: CW1 | K34: RULES | M34: =IF(M33="Deep",1100,"non std. Cabin type") -> 1100 | N34: =IF(N33="Deep",1100,IF(N33="Wide",1600,"Wrong shape")) -> 1100 | O34: =IF(O33="Deep",1200,IF(O33="Wide",2000,"Wrong shape")) -> 1200 | P34: =IF(P33="Wide",2000,"non std. Cabin type") -> 2000 | Q34: =IF(Q33="Deep",1400,IF(Q33="Wide",2100,"Wrong shape")) -> 2100 | R34: =IF(R33="Wide",2100,"Wrong shape") -> Wrong shape | S34: =IF(S33="Deep",1500,"Wrong shape") -> 1500 | T34: =IF(T33="Deep",1800,"Wrong shape") -> 1800 | U34: =IF(U33="Deep",2100,"Wrong shape") -> 2100
A35: Cabin depth (clear) | D35: [mm] | E35: yes | F35: Shaft0.Car.CD | G35: yes | H35: CD1 | K35: RULES | M35: =IF(M34=1100,1400, "non std. Cabin type") -> 1400 | N35: =IF(N34=1100,2100,IF(N34=1600,1400,"non standard width")) -> 2100 | O35: =IF(O34=2000,1500,IF(O34=1200,2300,"non std. Cabin type")) -> 2300 | P35: =IF(P34=2000, 1500,"non std. Cabin type") -> 1500 | Q35: =IF(Q34=1400,2400, IF(Q34=2100,1600,"non std. Cabin type")) -> 1600 | R35: =IF(R34=2100,1800,"non std. Cabin type") -> non std. Cabin type | S35: =IF(S34=1500,2700,"non std. Cabin type") -> 2700 | T35: =IF(T34=1800,2700,"non std. Cabin type") -> 2700 | U35: =IF(U34=2100,3000,"non std. Cabin type") -> 3000
A36: Cladding thickness each wall | D36: [mm] | E36: No | F36: - | G36: yes | H36: - | K36: If no cladding insert 0 | M36: 0 | N36: 0 | O36: 0 | P36: 10 | Q36: 0 | R36: 10 | S36: 10 | T36: 10 | U36: 10
A37: Clear cabin height | D37: [mm] | E37: yes | F37: no | G37: yes | H37: - | K37: Those are the standard values for each lift. Just 1600 has a 2 standard options | M37: 2200 | N37: 2200 | O37: 2300 | P37: 2300 | Q37: =IF(Q34=2100,2400,IF(Q34=1400,2300,"non std.CW")) -> 2400 | R37: 2400 | S37: 2300 | T37: 2300 | U37: 2400
A38: Structural cabin height | D38: [mm] | E38: yes | F38: Shaft0.Car.HEIGHT | G38: yes | H38: - | K38: RULES | M38: =M37+100 -> 2300 | N38: =N37+100 -> 2300 | O38: =O37+100 -> 2400 | P38: =P37+100 -> 2400 | Q38: =Q37+100 -> 2500 | R38: =R37+100 -> 2500 | S38: =S37+100 -> 2400 | T38: 2500 | U38: =U37+100 -> 2500
A39: TÜREINZUG VORNE | D39: [mm] | K39: Standard 30 mm | L39: TBC | M39: 30 | N39: 30 | O39: 30 | P39: 30 | Q39: 30 | R39: 30 | S39: 30 | T39: 30 | U39: 30
A40: MUZ??? | L40: TBC
A41: Door width | D41: [mm] | E41: yes | F41: yes, info | G41: yes | H41: - | M41: 900 | N41: =IF(N34=1100,900,IF(N34=1600,1000,"non standard Car width")) -> 900 | O41: 1100 | P41: 1100 | Q41: =IF(Q34=1400, 1300, IF(Q34=2100, 1200,"non std.CW")) -> 1200 | R41: 1200 | S41: 1300 | T41: 1500 | U41: 1800
A42: Door structural opening width | D42: [mm] | E42: yes | F42: Shaft0.Entries1.E0.Opening.T_AUSBR_B | G42: yes | H42: - | M42: =M41+2*140 -> 1180 | N42: =N41+2*140 -> 1180 | O42: =O41+2*140 -> 1380 | P42: =P41+2*140 -> 1380 | Q42: =Q41+2*140 -> 1480 | R42: =R41+2*140 -> 1480 | S42: =S41+2*140 -> 1580 | T42: =T41+2*140 -> 1780 | U42: =U41+2*140 -> 2080
A43: Door height | D43: [mm] | E43: yes | F43: yes, info | G43: yes | H43: - | K43: is this always clear cabin height -100? | M43: =M37-100 -> 2100 | N43: =N37-100 -> 2100 | O43: =O37-100 -> 2200 | P43: =P37-100 -> 2200 | Q43: =Q37-100 -> 2300 | R43: =R37-100 -> 2300 | S43: =S37-100 -> 2200 | T43: =T37-100 -> 2200 | U43: 2300
A44: Door structural opening height | D44: [mm] | E44: yes | F44: yes, info | G44: yes | H44: - | M44: =M43+140 -> 2240 | N44: =N43+140 -> 2240 | O44: =O43+140 -> 2340 | P44: =P43+140 -> 2340 | Q44: =Q43+140 -> 2440 | R44: =R43+140 -> 2440 | S44: =S43+140 -> 2340 | T44: =T43+140 -> 2340 | U44: =U43+140 -> 2440
...

Sheet revision
A1: Date | B1: Revised Cells | D1: Implemented
A2: 260320 | B2: M57:U57 | D2: TRUE
B3: P53,R53,S53,T53,U53 | D3: TRUE
B4: U33:U34 | D4: TRUE
D5: FALSE
A6: 260324 | B6: A233:U235 | D6: FALSE
A7: 260325 | B7: A236:U239 | D7: FALSE
A8: 260330 | B8: 114:117 | C8: Changed rows marked red | D8: TRUE
A9: 260407 | B9: 400,405,410,415 | C9: Formulas and Ld codes changed (simplified) | D9: FALSE

Sheet selection
A1: System category | B1: Traction - MRL | C1: Traction - MR | D1: Hydraulic MR | E1: Escalator
A2: Construction use | B2: yes | C2: no
A3: Counterweight location | B3: CWT-Left | C3: CWT-Right | D3: CWT-Rear | E3: no CWT
A4: Speed | B4: 1 | C4: 1.6 | D4: 2
A5: Access type | B5: Front | C5: Rear | D5: Front + Rear | E5: Front + Side | F5: Front + Side + Rear
A6: accessible rooms / cwt safety | B6: yes | C6: no
A7: Cabin type/shape | B7: Wide | C7: Deep
A8: Door type | B8: 2C | C8: 4C | D8: 6C | E8: 2L | F8: 2R
A9: Door fixation type | B9: insert rail 40/22 | C9: insert rail 50/30 | D9: anchor bolts | E9: steel structure
A10: Permissible sill load / Loading class | B10: ASME-A | C10: ASME-B | D10: ASME-C1 | E10: ASME-C2 | F10: EN81-40% | G10: EN81-60% | H10: EN81-85%
A11: LOP type and location | B11: in lift door frame L | C11: in lift door frame R | D11: flush wall panel L | E11: flush wall panel R | F11: wall-mounted panel L | G11: wall-mounted panel R
A12: LIP type and location | B12: door frame side vertical | C12: door frame above horizontal | D12: panel above horizontal | E12: panel side vertical
A13: Lift maintenance panel type | B13: inside door jamb | C13: segregated panel flush | D13: segregated panel wall-mounted
A14: Shaft equipment fixation type | B14: insert rail 40/22 | C14: insert rail 50/30 | D14: anchor bolts | E14: steel structure
A15: Dividing type | B15: structural wall | C15: beam
A16: Drive/Motor location | B16: MRL top | C16: Machine room top | D16: Machine room side | E16: Machine room bottom
A17: Drive/Motor type | B17: VVVF
A18: Power grid voltage/type | B18: 380 | C18: 400
A19: Energy recovery | B19: yes | C19: no
A20: Counterweight safety gear | B20: yes | C20: no
A21: EN81-28 emergency call | B21: yes | C21: no
A22: EN81-70 Accessibility | B22: yes | C22: no
A23: DIN EN17210 / 18040-1 Accessibility | B23: yes | C23: no
A24: EN81-71 Vandalism category | B24: 0 | C24: 1 | D24: 2 | E24: 3
A25: EN81-72 Firefighter elevator | B25: yes | C25: no
A26: EN81-73 Fire emergency return | B26: yes | C26: no
A27: EN81-76 Emergency Evacuation Type | B27: no | C27: yes, TYPE A | D27: yes, TYPE B
A28: EN81-77 Seismic category | B28: 0 | C28: 1 | D28: 2 | E28: 3
A29: FAS interfaces as per spec | B29: yes | C29: no
A30: Emergency power | B30: yes | C30: no
A31: Cascading evacuation control | B31: yes | C31: no
A32: Type of emergency power | B32: UPS | C32: Generator
A33: FCC panel interface as per spec | B33: yes | C33: no
A34: 2-way intercom firefighter lift | B34: yes | C34: no
A35: BMS interfaces as per spec | B35: yes | C35: no
A36: Lift monitoring | B36: yes | C36: no
A37: ICT/AV interfaces as per spec | B37: yes | C37: no
A38: In-car CCTV | B38: yes | C38: no
A39: Access Control interface as per spec | B39: yes | C39: no
A40: other Security interfaces as per spec. | B40: yes | C40: no
...

Sheet info
A1: Levels, names, entrances guide
K3: 0 - no entrance
K4: 1 - front entrance
K5: 2- rear entrance
K6: 3- both entrance
A7: LVL names | B7: Front entrances | C7: height | D7: Rear entrances | G7: Level height code | H7: value (height) | J7: Lift entrances code | K7: values : | M7: Lvl name codes | N7: Value (Lvl name)
B8: FALSE | D8: FALSE
B9: FALSE | D9: FALSE
B10: FALSE | D10: FALSE
B11: FALSE | D11: FALSE
B12: FALSE | D12: FALSE
B13: FALSE | D13: FALSE
B14: FALSE | D14: FALSE
A15: L07 | B15: TRUE | C15: 20000 | D15: TRUE | G15: FLL.Level6.Z_POT | H15: 20000 | J15: FLL.Level6.SERVICE0 | K15: 3 | M15: FLL.Level6.DESC | N15: L07
A16: L06 | B16: FALSE | C16: 15000 | D16: FALSE | G16: FLL.Level5.Z_POT | H16: 15000 | J16: FLL.Level5.SERVICE0 | K16: 0 | M16: FLL.Level5.DESC | N16: L06
A17: L05 | B17: TRUE | C17: 10000 | D17: TRUE | G17: FLL.Level4.Z_POT | H17: 10000 | J17: FLL.Level4.SERVICE0 | K17: 3 | M17: FLL.Level4.DESC | N17: L05
A18: L04 | B18: FALSE | C18: 5000 | D18: TRUE | G18: FLL.Level3.Z_POT | H18: 5000 | J18: FLL.Level3.SERVICE0 | K18: 2 | M18: FLL.Level3.DESC | N18: L04
A19: L03 | B19: TRUE | C19: 0 | D19: TRUE | G19: FLL.Level2.Z_POT | H19: 0 | J19: FLL.Level2.SERVICE0 | K19: 3 | M19: FLL.Level2.DESC | N19: L03
A20: L02 | B20: TRUE | C20: -5000 | D20: TRUE | G20: FLL.Level1.Z_POT | H20: -5000 | J20: FLL.Level1.SERVICE0 | K20: 3 | M20: FLL.Level1.DESC | N20: L02
A21: L00 | B21: TRUE | C21: -10000 | D21: FALSE | G21: FLL.Level0.Z_POT | H21: -10000 | J21: FLL.Level0.SERVICE0 | K21: 1 | M21: FLL.Level0.DESC | N21: L00
A26: Exporting second shaft
A27: *we need an option to export and import data of shaft as a second or third one in a set
A28: To correctly export data of second shaft Shaft0. needs to be replaced by Shaft1. or Shaft2. in every single code
A29: * there is exception. If we export second shaft we need to perform changes :
A31: if we export as a Shaft1.
A32: L_Projects.PROJ_USER_0 | D32: with | E32: L_Projects.PROJ_USER_4
A33: L_Projects.PROJ_USER_2 | D33: with | E33: L_Projects.PROJ_USER_5
A34: L_Projects.PROJ_USER_3 | D34: with | E34: L_Projects.PROJ_USER_6
A35: if we export as a Shaft2.
A36: L_Projects.PROJ_USER_0 | D36: with | E36: L_Projects.PROJ_USER_7
A37: L_Projects.PROJ_USER_2 | D37: with | E37: L_Projects.PROJ_USER_8
A38: L_Projects.PROJ_USER_3 | D38: with | E38: L_Projects.PROJ_USER_9
A39: If we export as a Shaft3.
A40: L_Projects.PROJ_USER_0 | D40: with | E40: L_Projects.PROJ_USER_10
A41: L_Projects.PROJ_USER_2 | D41: with | E41: L_Projects.PROJ_USER_11
A42: L_Projects.PROJ_USER_3 | D42: with | E42: L_Projects.PROJ_USER_12
A48: Shaft depth:
A49: We have 3 options right now: Front, Rear or Front + Rear
A50: depending on which one we picked in row 28 the diferent sets we should export (our sets are fron 287 to 324)
A54: Outside export file that will be ready to put info LD we should also have a table/paper that will have all the information that is impossible to import to LD and we need to do manualy. Also this paper will have the same informations that export should have. (Lift designer likes to not change stuff properly so to perform doubble check)

Sheet Tabelle1
C6: Speed | E6: YES/NO
C7: 1 | E7: Ja/Yes
C8: 1.6 | E8: Nein/No
C9: 2
C10: 2.5
